{"name": "test_failure", "status": "failed", "statusDetails": {"message": "AssertionError: assert False", "trace": "def test_failure():\n        \"\"\"this test fails\"\"\"\n>       assert False\nE       assert False\n\ntest_func.py:10: AssertionError"}, "description": "this test fails", "start": 1648451881018, "stop": 1648451881020, "uuid": "110e805c-cf08-42f2-88fd-210422eb6aa7", "historyId": "67b02db31f2c819ba916d471a700a621", "testCaseId": "dd8931fb31467782b4f967db13a07b6b", "fullName": "test_func#test_failure", "labels": [{"name": "suite", "value": "test_func"}, {"name": "host", "value": "NTCLT0302"}, {"name": "thread", "value": "432-MainThread"}, {"name": "framework", "value": "pytest"}, {"name": "language", "value": "cpython3"}, {"name": "package", "value": "test_func"}]}